[2025-04-21T09:59:37.931+0000] {local_task_job_runner.py:123} INFO - ::group::Pre task execution logs
[2025-04-21T09:59:37.950+0000] {taskinstance.py:2614} INFO - Dependencies all met for dep_context=non-requeueable deps ti=<TaskInstance: dag_rezaseptian.insert_filtered_data manual__2025-04-21T09:59:29.870607+00:00 [queued]>
[2025-04-21T09:59:37.961+0000] {taskinstance.py:2614} INFO - Dependencies all met for dep_context=requeueable deps ti=<TaskInstance: dag_rezaseptian.insert_filtered_data manual__2025-04-21T09:59:29.870607+00:00 [queued]>
[2025-04-21T09:59:37.962+0000] {taskinstance.py:2867} INFO - Starting attempt 1 of 1
[2025-04-21T09:59:37.975+0000] {taskinstance.py:2890} INFO - Executing <Task(SQLExecuteQueryOperator): insert_filtered_data> on 2025-04-21 09:59:29.870607+00:00
[2025-04-21T09:59:37.981+0000] {warnings.py:112} WARNING - /home/***/.local/lib/python3.12/site-packages/***/task/task_runner/standard_task_runner.py:70: DeprecationWarning: This process (pid=693) is multi-threaded, use of fork() may lead to deadlocks in the child.
  pid = os.fork()

[2025-04-21T09:59:37.982+0000] {standard_task_runner.py:72} INFO - Started process 695 to run task
[2025-04-21T09:59:37.983+0000] {standard_task_runner.py:104} INFO - Running: ['***', 'tasks', 'run', 'dag_rezaseptian', 'insert_filtered_data', 'manual__2025-04-21T09:59:29.870607+00:00', '--job-id', '29', '--raw', '--subdir', 'DAGS_FOLDER/dag_rezaseptian.py', '--cfg-path', '/tmp/tmpcdzo0k7v']
[2025-04-21T09:59:37.984+0000] {standard_task_runner.py:105} INFO - Job 29: Subtask insert_filtered_data
[2025-04-21T09:59:38.031+0000] {task_command.py:467} INFO - Running <TaskInstance: dag_rezaseptian.insert_filtered_data manual__2025-04-21T09:59:29.870607+00:00 [running]> on host 3c6ae2537c9a
[2025-04-21T09:59:38.364+0000] {taskinstance.py:3134} INFO - Exporting env vars: AIRFLOW_CTX_DAG_OWNER='***' AIRFLOW_CTX_DAG_ID='dag_rezaseptian' AIRFLOW_CTX_TASK_ID='insert_filtered_data' AIRFLOW_CTX_EXECUTION_DATE='2025-04-21T09:59:29.870607+00:00' AIRFLOW_CTX_TRY_NUMBER='1' AIRFLOW_CTX_DAG_RUN_ID='manual__2025-04-21T09:59:29.870607+00:00'
[2025-04-21T09:59:38.366+0000] {logging_mixin.py:190} INFO - Task instance is in running state
[2025-04-21T09:59:38.367+0000] {logging_mixin.py:190} INFO -  Previous state of the Task instance: queued
[2025-04-21T09:59:38.368+0000] {logging_mixin.py:190} INFO - Current task name:insert_filtered_data state:running start_date:2025-04-21 09:59:37.951467+00:00
[2025-04-21T09:59:38.368+0000] {logging_mixin.py:190} INFO - Dag name:dag_rezaseptian and current dag run status:running
[2025-04-21T09:59:38.369+0000] {taskinstance.py:732} INFO - ::endgroup::
[2025-04-21T09:59:38.370+0000] {sql.py:295} INFO - Executing: 
    TRUNCATE TABLE another_table;
    
    INSERT INTO another_table (id, customer_name, data_usage_gb)
    SELECT id, customer_name, data_usage_gb
    FROM telecom_users
    WHERE data_usage_gb > 10
    ON CONFLICT (id) DO NOTHING;
[2025-04-21T09:59:38.380+0000] {base.py:84} INFO - Retrieving connection 'postgre_conn'
[2025-04-21T09:59:38.390+0000] {base.py:84} INFO - Retrieving connection 'postgre_conn'
[2025-04-21T09:59:38.545+0000] {sql.py:511} INFO - Running statement: 
    TRUNCATE TABLE another_table;
    
    INSERT INTO another_table (id, customer_name, data_usage_gb)
    SELECT id, customer_name, data_usage_gb
    FROM telecom_users
    WHERE data_usage_gb > 10
    ON CONFLICT (id) DO NOTHING;, parameters: None
[2025-04-21T09:59:38.604+0000] {taskinstance.py:3313} ERROR - Task failed with exception
Traceback (most recent call last):
  File "/home/airflow/.local/lib/python3.12/site-packages/airflow/models/taskinstance.py", line 768, in _execute_task
    result = _execute_callable(context=context, **execute_callable_kwargs)
             ^^^^^^^^^^^^^^^^^^^^^^^^^^^^^^^^^^^^^^^^^^^^^^^^^^^^^^^^^^^^^
  File "/home/airflow/.local/lib/python3.12/site-packages/airflow/models/taskinstance.py", line 734, in _execute_callable
    return ExecutionCallableRunner(
           ^^^^^^^^^^^^^^^^^^^^^^^^
  File "/home/airflow/.local/lib/python3.12/site-packages/airflow/utils/operator_helpers.py", line 252, in run
    return self.func(*args, **kwargs)
           ^^^^^^^^^^^^^^^^^^^^^^^^^^
  File "/home/airflow/.local/lib/python3.12/site-packages/airflow/models/baseoperator.py", line 424, in wrapper
    return func(self, *args, **kwargs)
           ^^^^^^^^^^^^^^^^^^^^^^^^^^^
  File "/home/airflow/.local/lib/python3.12/site-packages/airflow/providers/common/sql/operators/sql.py", line 301, in execute
    output = hook.run(
             ^^^^^^^^^
  File "/home/airflow/.local/lib/python3.12/site-packages/airflow/providers/common/sql/hooks/sql.py", line 467, in run
    self._run_command(cur, sql_statement, parameters)
  File "/home/airflow/.local/lib/python3.12/site-packages/airflow/providers/common/sql/hooks/sql.py", line 516, in _run_command
    cur.execute(sql_statement)
psycopg2.errors.UndefinedColumn: column "data_usage_gb" of relation "another_table" does not exist
LINE 4:     INSERT INTO another_table (id, customer_name, data_usage...
                                                          ^

[2025-04-21T09:59:38.614+0000] {logging_mixin.py:190} INFO - Task instance in failure state
[2025-04-21T09:59:38.615+0000] {logging_mixin.py:190} INFO - Task start:2025-04-21 09:59:37.951467+00:00 end:2025-04-21 09:59:38.613946+00:00 duration:0.662479
[2025-04-21T09:59:38.616+0000] {logging_mixin.py:190} INFO - Task:<Task(SQLExecuteQueryOperator): insert_filtered_data> dag:<DAG: dag_rezaseptian> dagrun:<DagRun dag_rezaseptian @ 2025-04-21 09:59:29.870607+00:00: manual__2025-04-21T09:59:29.870607+00:00, state:running, queued_at: 2025-04-21 09:59:29.879494+00:00. externally triggered: True>
[2025-04-21T09:59:38.617+0000] {logging_mixin.py:190} INFO - Failure caused by column "data_usage_gb" of relation "another_table" does not exist
LINE 4:     INSERT INTO another_table (id, customer_name, data_usage...
                                                          ^
[2025-04-21T09:59:38.617+0000] {taskinstance.py:1226} INFO - Marking task as FAILED. dag_id=dag_rezaseptian, task_id=insert_filtered_data, run_id=manual__2025-04-21T09:59:29.870607+00:00, execution_date=20250421T095929, start_date=20250421T095937, end_date=20250421T095938
[2025-04-21T09:59:38.647+0000] {taskinstance.py:341} INFO - ::group::Post task execution logs
[2025-04-21T09:59:38.647+0000] {standard_task_runner.py:124} ERROR - Failed to execute job 29 for task insert_filtered_data (column "data_usage_gb" of relation "another_table" does not exist
LINE 4:     INSERT INTO another_table (id, customer_name, data_usage...
                                                          ^
; 695)
Traceback (most recent call last):
  File "/home/airflow/.local/lib/python3.12/site-packages/airflow/task/task_runner/standard_task_runner.py", line 117, in _start_by_fork
    ret = args.func(args, dag=self.dag)
          ^^^^^^^^^^^^^^^^^^^^^^^^^^^^^
  File "/home/airflow/.local/lib/python3.12/site-packages/airflow/cli/cli_config.py", line 49, in command
    return func(*args, **kwargs)
           ^^^^^^^^^^^^^^^^^^^^^
  File "/home/airflow/.local/lib/python3.12/site-packages/airflow/utils/cli.py", line 116, in wrapper
    return f(*args, **kwargs)
           ^^^^^^^^^^^^^^^^^^
  File "/home/airflow/.local/lib/python3.12/site-packages/airflow/cli/commands/task_command.py", line 483, in task_run
    task_return_code = _run_task_by_selected_method(args, _dag, ti)
                       ^^^^^^^^^^^^^^^^^^^^^^^^^^^^^^^^^^^^^^^^^^^^
  File "/home/airflow/.local/lib/python3.12/site-packages/airflow/cli/commands/task_command.py", line 256, in _run_task_by_selected_method
    return _run_raw_task(args, ti)
           ^^^^^^^^^^^^^^^^^^^^^^^
  File "/home/airflow/.local/lib/python3.12/site-packages/airflow/cli/commands/task_command.py", line 341, in _run_raw_task
    return ti._run_raw_task(
           ^^^^^^^^^^^^^^^^^
  File "/home/airflow/.local/lib/python3.12/site-packages/airflow/utils/session.py", line 97, in wrapper
    return func(*args, session=session, **kwargs)
           ^^^^^^^^^^^^^^^^^^^^^^^^^^^^^^^^^^^^^^
  File "/home/airflow/.local/lib/python3.12/site-packages/airflow/models/taskinstance.py", line 3006, in _run_raw_task
    return _run_raw_task(
           ^^^^^^^^^^^^^^
  File "/home/airflow/.local/lib/python3.12/site-packages/airflow/models/taskinstance.py", line 274, in _run_raw_task
    TaskInstance._execute_task_with_callbacks(
  File "/home/airflow/.local/lib/python3.12/site-packages/airflow/models/taskinstance.py", line 3161, in _execute_task_with_callbacks
    result = self._execute_task(context, task_orig)
             ^^^^^^^^^^^^^^^^^^^^^^^^^^^^^^^^^^^^^^
  File "/home/airflow/.local/lib/python3.12/site-packages/airflow/models/taskinstance.py", line 3185, in _execute_task
    return _execute_task(self, context, task_orig)
           ^^^^^^^^^^^^^^^^^^^^^^^^^^^^^^^^^^^^^^^
  File "/home/airflow/.local/lib/python3.12/site-packages/airflow/models/taskinstance.py", line 768, in _execute_task
    result = _execute_callable(context=context, **execute_callable_kwargs)
             ^^^^^^^^^^^^^^^^^^^^^^^^^^^^^^^^^^^^^^^^^^^^^^^^^^^^^^^^^^^^^
  File "/home/airflow/.local/lib/python3.12/site-packages/airflow/models/taskinstance.py", line 734, in _execute_callable
    return ExecutionCallableRunner(
           ^^^^^^^^^^^^^^^^^^^^^^^^
  File "/home/airflow/.local/lib/python3.12/site-packages/airflow/utils/operator_helpers.py", line 252, in run
    return self.func(*args, **kwargs)
           ^^^^^^^^^^^^^^^^^^^^^^^^^^
  File "/home/airflow/.local/lib/python3.12/site-packages/airflow/models/baseoperator.py", line 424, in wrapper
    return func(self, *args, **kwargs)
           ^^^^^^^^^^^^^^^^^^^^^^^^^^^
  File "/home/airflow/.local/lib/python3.12/site-packages/airflow/providers/common/sql/operators/sql.py", line 301, in execute
    output = hook.run(
             ^^^^^^^^^
  File "/home/airflow/.local/lib/python3.12/site-packages/airflow/providers/common/sql/hooks/sql.py", line 467, in run
    self._run_command(cur, sql_statement, parameters)
  File "/home/airflow/.local/lib/python3.12/site-packages/airflow/providers/common/sql/hooks/sql.py", line 516, in _run_command
    cur.execute(sql_statement)
psycopg2.errors.UndefinedColumn: column "data_usage_gb" of relation "another_table" does not exist
LINE 4:     INSERT INTO another_table (id, customer_name, data_usage...
                                                          ^

[2025-04-21T09:59:38.682+0000] {local_task_job_runner.py:266} INFO - Task exited with return code 1
[2025-04-21T09:59:38.705+0000] {taskinstance.py:3901} INFO - 0 downstream tasks scheduled from follow-on schedule check
[2025-04-21T09:59:38.711+0000] {local_task_job_runner.py:245} INFO - ::endgroup::
